Workbook

Sheet reporting conso 4 batiments
F2: 2025 | G2: 2025 | H2: 2025 | I2: 2025 | J2: 2025 | K2: 2025 | L2: 2025 | M2: 2025 | N2: 2025 | O2: 2025 | P2: 2025 | Q2: 2025 | R2: 2025 | S2: 2026 | T2: 2026 | U2: 2026 | V2: 2026 | W2: 2026 | X2: 2026 | Y2: 2026 | Z2: 2026 | AA2: 2026 | AB2: 2026 | AC2: 2026 | AD2: 2026 | AE2: 2026 | AF2: 2027 | AG2: 2027 | AH2: 2027 | AI2: 2027 | AJ2: 2027 | AK2: 2027 | AL2: 2027 | AM2: 2027 | AN2: 2027 | AO2: 2027 | AP2: 2027 | AQ2: 2027 | AR2: 2027 | AS2: 2028 | AT2: 2028 | AU2: 2028 | AV2: 2028 | AW2: 2028 | AX2: 2028 | AY2: 2028 | AZ2: 2028 | BA2: 2028 | BB2: 2028 | BC2: 2028 | BD2: 2028 | BE2: 2028 | BF2: 2029 | BG2: 2029 | BH2: 2029 | BI2: 2029 | BJ2: 2029 | BK2: 2029 | BL2: 2029 | BM2: 2029 | BN2: 2029 | BO2: 2029 | BP2: 2029 | BQ2: 2029 | BR2: 2029 | BS2: 2030 | BT2: 2030 | BU2: 2030 | BV2: 2030 | BW2: 2030 | BX2: 2030 | BY2: 2030 | BZ2: 2030 | CA2: 2030 | CB2: 2030 | CC2: 2030 | CD2: 2030 | CE2: 2030 | CF2: 2031 | CG2: 2031 | CH2: 2031 | CI2: 2031 | CJ2: 2031 | CK2: 2031 | CL2: 2031 | CM2: 2031 | CN2: 2031 | CO2: 2031 | CP2: 2031 | CQ2: 2031 | CR2: 2031 | CS2: 2032 | CT2: 2032 | CU2: 2032 | CV2: 2032 | CW2: 2032 | CX2: 2032 | CY2: 2032 | CZ2: 2032 | DA2: 2032 | DB2: 2032 | DC2: 2032 | DD2: 2032 | DE2: 2032 | DF2: 2033 | DG2: 2033 | DH2: 2033 | DI2: 2033 | DJ2: 2033 | DK2: 2033 | DL2: 2033 | DM2: 2033 | DN2: 2033 | DO2: 2033 | DP2: 2033 | DQ2: 2033 | DR2: 2033
B3: Nombres de sites | C3: 9 | F3: 1 | G3: 2 | H3: 3 | I3: 4 | J3: 5 | K3: 6 | L3: 7 | M3: 8 | N3: 9 | O3: 10 | P3: 11 | Q3: 12 | R3: 2025 | S3: 1 | T3: 2 | U3: 3 | V3: 4 | W3: 5 | X3: 6 | Y3: 7 | Z3: 8 | AA3: 9 | AB3: 10 | AC3: 11 | AD3: 12 | AE3: 2026 | AF3: 1 | AG3: 2 | AH3: 3 | AI3: 4 | AJ3: 5 | AK3: 6 | AL3: 7 | AM3: 8 | AN3: 9 | AO3: 10 | AP3: 11 | AQ3: 12 | AR3: 2027 | AS3: 1 | AT3: 2 | AU3: 3 | AV3: 4 | AW3: 5 | AX3: 6 | AY3: 7 | AZ3: 8 | BA3: 9 | BB3: 10 | BC3: 11 | BD3: 12 | BE3: 2028 | BF3: 1 | BG3: 2 | BH3: 3 | BI3: 4 | BJ3: 5 | BK3: 6 | BL3: 7 | BM3: 8 | BN3: 9 | BO3: 10 | BP3: 11 | BQ3: 12 | BR3: 2029 | BS3: 1 | BT3: 2 | BU3: 3 | BV3: 4 | BW3: 5 | BX3: 6 | BY3: 7 | BZ3: 8 | CA3: 9 | CB3: 10 | CC3: 11 | CD3: 12 | CE3: 2030 | CF3: 1 | CG3: 2 | CH3: 3 | CI3: 4 | CJ3: 5 | CK3: 6 | CL3: 7 | CM3: 8 | CN3: 9 | CO3: 10 | CP3: 11 | CQ3: 12 | CR3: 2031 | CS3: 1 | CT3: 2 | CU3: 3 | CV3: 4 | CW3: 5 | CX3: 6 | CY3: 7 | CZ3: 8 | DA3: 9 | DB3: 10 | DC3: 11 | DD3: 12 | DE3: 2032 | DF3: 1 | DG3: 2 | DH3: 3 | DI3: 4 | DJ3: 5 | DK3: 6 | DL3: 7 | DM3: 8 | DN3: 9 | DO3: 10 | DP3: 11 | DQ3: 12 | DR3: 2033
F4: =EOMONTH(DATE(F2,F3,1),0) -> 45688 | G4: =EOMONTH(DATE(G2,G3,1),0) -> 45716 | H4: =EOMONTH(DATE(H2,H3,1),0) -> 45747 | I4: =EOMONTH(DATE(I2,I3,1),0) -> 45777 | J4: =EOMONTH(DATE(J2,J3,1),0) -> 45808 | K4: =EOMONTH(DATE(K2,K3,1),0) -> 45838 | L4: =EOMONTH(DATE(L2,L3,1),0) -> 45869 | M4: =EOMONTH(DATE(M2,M3,1),0) -> 45900 | ... Q4: =EOMONTH(DATE(Q2,Q3,1),0) -> 46022 | R4: =R3 -> 2025 | S4: =EOMONTH(DATE(S2,S3,1),0) -> 46053 | T4: =EOMONTH(DATE(T2,T3,1),0) -> 46081 | U4: =EOMONTH(DATE(U2,U3,1),0) -> 46112 | V4: =EOMONTH(DATE(V2,V3,1),0) -> 46142 | W4: =EOMONTH(DATE(W2,W3,1),0) -> 46173 | X4: =EOMONTH(DATE(X2,X3,1),0) -> 46203 | Y4: =EOMONTH(DATE(Y2,Y3,1),0) -> 46234 | Z4: =EOMONTH(DATE(Z2,Z3,1),0) -> 46265 | ... AD4: =EOMONTH(DATE(AD2,AD3,1),0) -> 46387 | AE4: =AE3 -> 2026 | AF4: =EOMONTH(DATE(AF2,AF3,1),0) -> 46418 | AG4: =EOMONTH(DATE(AG2,AG3,1),0) -> 46446 | AH4: =EOMONTH(DATE(AH2,AH3,1),0) -> 46477 | AI4: =EOMONTH(DATE(AI2,AI3,1),0) -> 46507 | AJ4: =EOMONTH(DATE(AJ2,AJ3,1),0) -> 46538 | AK4: =EOMONTH(DATE(AK2,AK3,1),0) -> 46568 | AL4: =EOMONTH(DATE(AL2,AL3,1),0) -> 46599 | AM4: =EOMONTH(DATE(AM2,AM3,1),0) -> 46630 | ... AQ4: =EOMONTH(DATE(AQ2,AQ3,1),0) -> 46752 | AR4: =AR3 -> 2027 | AS4: =EOMONTH(DATE(AS2,AS3,1),0) -> 46783 | AT4: =EOMONTH(DATE(AT2,AT3,1),0) -> 46812 | AU4: =EOMONTH(DATE(AU2,AU3,1),0) -> 46843 | AV4: =EOMONTH(DATE(AV2,AV3,1),0) -> 46873 | AW4: =EOMONTH(DATE(AW2,AW3,1),0) -> 46904 | AX4: =EOMONTH(DATE(AX2,AX3,1),0) -> 46934 | AY4: =EOMONTH(DATE(AY2,AY3,1),0) -> 46965 | AZ4: =EOMONTH(DATE(AZ2,AZ3,1),0) -> 46996 | ... BD4: =EOMONTH(DATE(BD2,BD3,1),0) -> 47118 | BE4: =BE3 -> 2028 | BF4: =EOMONTH(DATE(BF2,BF3,1),0) -> 47149 | BG4: =EOMONTH(DATE(BG2,BG3,1),0) -> 47177 | BH4: =EOMONTH(DATE(BH2,BH3,1),0) -> 47208 | BI4: =EOMONTH(DATE(BI2,BI3,1),0) -> 47238 | BJ4: =EOMONTH(DATE(BJ2,BJ3,1),0) -> 47269 | BK4: =EOMONTH(DATE(BK2,BK3,1),0) -> 47299 | BL4: =EOMONTH(DATE(BL2,BL3,1),0) -> 47330 | BM4: =EOMONTH(DATE(BM2,BM3,1),0) -> 47361 | ... BQ4: =EOMONTH(DATE(BQ2,BQ3,1),0) -> 47483 | BR4: =BR3 -> 2029 | BS4: =EOMONTH(DATE(BS2,BS3,1),0) -> 47514 | BT4: =EOMONTH(DATE(BT2,BT3,1),0) -> 47542 | BU4: =EOMONTH(DATE(BU2,BU3,1),0) -> 47573 | BV4: =EOMONTH(DATE(BV2,BV3,1),0) -> 47603 | BW4: =EOMONTH(DATE(BW2,BW3,1),0) -> 47634 | BX4: =EOMONTH(DATE(BX2,BX3,1),0) -> 47664 | BY4: =EOMONTH(DATE(BY2,BY3,1),0) -> 47695 | BZ4: =EOMONTH(DATE(BZ2,BZ3,1),0) -> 47726 | ... CD4: =EOMONTH(DATE(CD2,CD3,1),0) -> 47848 | CE4: =CE3 -> 2030 | CF4: =EOMONTH(DATE(CF2,CF3,1),0) -> 47879 | CG4: =EOMONTH(DATE(CG2,CG3,1),0) -> 47907 | CH4: =EOMONTH(DATE(CH2,CH3,1),0) -> 47938 | CI4: =EOMONTH(DATE(CI2,CI3,1),0) -> 47968 | CJ4: =EOMONTH(DATE(CJ2,CJ3,1),0) -> 47999 | CK4: =EOMONTH(DATE(CK2,CK3,1),0) -> 48029 | CL4: =EOMONTH(DATE(CL2,CL3,1),0) -> 48060 | CM4: =EOMONTH(DATE(CM2,CM3,1),0) -> 48091 | ... CQ4: =EOMONTH(DATE(CQ2,CQ3,1),0) -> 48213 | CR4: =CR3 -> 2031 | CS4: =EOMONTH(DATE(CS2,CS3,1),0) -> 48244 | CT4: =EOMONTH(DATE(CT2,CT3,1),0) -> 48273 | CU4: =EOMONTH(DATE(CU2,CU3,1),0) -> 48304 | CV4: =EOMONTH(DATE(CV2,CV3,1),0) -> 48334 | CW4: =EOMONTH(DATE(CW2,CW3,1),0) -> 48365 | CX4: =EOMONTH(DATE(CX2,CX3,1),0) -> 48395 | CY4: =EOMONTH(DATE(CY2,CY3,1),0) -> 48426 | CZ4: =EOMONTH(DATE(CZ2,CZ3,1),0) -> 48457 | ... DD4: =EOMONTH(DATE(DD2,DD3,1),0) -> 48579 | DE4: =DE3 -> 2032 | DF4: =EOMONTH(DATE(DF2,DF3,1),0) -> 48610 | DG4: =EOMONTH(DATE(DG2,DG3,1),0) -> 48638 | DH4: =EOMONTH(DATE(DH2,DH3,1),0) -> 48669 | DI4: =EOMONTH(DATE(DI2,DI3,1),0) -> 48699 | DJ4: =EOMONTH(DATE(DJ2,DJ3,1),0) -> 48730 | DK4: =EOMONTH(DATE(DK2,DK3,1),0) -> 48760 | DL4: =EOMONTH(DATE(DL2,DL3,1),0) -> 48791 | DM4: =EOMONTH(DATE(DM2,DM3,1),0) -> 48822 | ... DQ4: =EOMONTH(DATE(DQ2,DQ3,1),0) -> 48944 | DR4: =DR3 -> 2033
